<?xml version="1.0"?>
<robot name="myfirst">
  <link name="base_link">
    <visual>
      <geometry>
        <cylinder length="0.6" radius="0.2"/>
      </geometry>
    </visual>
  </link>

  <link name="second_link">
    <visual>
      <geometry>
        <cylinder length="0.4" radius="0.03"/>
      </geometry>
     <origin rpy="0 1.5 0" xyz="0.3 0 0"/>
    </visual>
  </link>

  <joint name="joint_1" type="continuous">
    <parent link="base_link"/>
    <child link="second_link"/>
    <origin xyz="-0.2 0 0"/>
  </joint>
  
  <link name="third_link">
   <visual>
    <geometry>
      <cylinder length="0.4" radius="0.03"/>
    </geometry>
    <origin rpy="0 1.5 0" xyz="-0.3 0 0"/>
   </visual>
  </link>
 
 <joint name="joint_2" type="revolute">
   <parent link="base_link"/>
   <child link="third_link"/>
   <limit effort="1000.0" lower="-3.14" upper="3.14" velocity="0.5"/>
   <origin xyz="0.2 0 0"/>
 </joint> 

 <link name="fourth_link">
  <visual>
   <geometry>
     <box size="0.2 0.2 0.2" />
    </geometry>  
    <origin rpy="0 0 0" xyz=" 0 0 0.3"/>
  </visual>
 </link>
 
 <joint name="joint_3" type="fixed">
   <parent link="base_link"/>
   <child link="fourth_link"/>
   <origin xyz="0 0 0.3"/>
 </joint>

</robot>
